wandb: Using wandb-core as the SDK backend.  Please refer to https://wandb.me/wandb-core for more information.
wandb: WARNING Path run/kfp-Qwen2.5-7B-Instruct/wandb/ wasn't writable, using system temp directory.
wandb: - Waiting for wandb.init()...wandb: \ Waiting for wandb.init()...wandb: | Waiting for wandb.init()...wandb: Tracking run with wandb version 0.18.7
wandb: W&B syncing is set to `offline` in this directory.  
wandb: Run `wandb online` or set WANDB_MODE=online to enable cloud syncing.
Traceback (most recent call last):
  File "/cvmfs/soft.computecanada.ca/easybuild/software/2023/x86-64-v3/Compiler/gcccore/python/3.12.4/lib/python3.12/importlib/metadata/__init__.py", line 397, in from_name
    return next(cls.discover(name=name))
           ^^^^^^^^^^^^^^^^^^^^^^^^^^^^^
StopIteration

During handling of the above exception, another exception occurred:

Traceback (most recent call last):
  File "/scratch/ilyes/kfp-gen/finetuning/unsloth_trainer/train_sft.py", line 130, in <module>
    main()
  File "/scratch/ilyes/kfp-gen/finetuning/unsloth_trainer/train_sft.py", line 27, in main
    nf4_config = BitsAndBytesConfig(
                 ^^^^^^^^^^^^^^^^^^^
  File "/home/ilyes/ENV/lib/python3.12/site-packages/transformers/utils/quantization_config.py", line 419, in __init__
    self.post_init()
  File "/home/ilyes/ENV/lib/python3.12/site-packages/transformers/utils/quantization_config.py", line 477, in post_init
    if self.load_in_4bit and not version.parse(importlib.metadata.version("bitsandbytes")) >= version.parse(
                                               ^^^^^^^^^^^^^^^^^^^^^^^^^^^^^^^^^^^^^^^^^^
  File "/cvmfs/soft.computecanada.ca/easybuild/software/2023/x86-64-v3/Compiler/gcccore/python/3.12.4/lib/python3.12/importlib/metadata/__init__.py", line 889, in version
    return distribution(distribution_name).version
           ^^^^^^^^^^^^^^^^^^^^^^^^^^^^^^^
  File "/cvmfs/soft.computecanada.ca/easybuild/software/2023/x86-64-v3/Compiler/gcccore/python/3.12.4/lib/python3.12/importlib/metadata/__init__.py", line 862, in distribution
    return Distribution.from_name(distribution_name)
           ^^^^^^^^^^^^^^^^^^^^^^^^^^^^^^^^^^^^^^^^^
  File "/cvmfs/soft.computecanada.ca/easybuild/software/2023/x86-64-v3/Compiler/gcccore/python/3.12.4/lib/python3.12/importlib/metadata/__init__.py", line 399, in from_name
    raise PackageNotFoundError(name)
importlib.metadata.PackageNotFoundError: No package metadata was found for bitsandbytes
[1;34mwandb[0m:
[1;34mwandb[0m: You can sync this run to the cloud by running:
[1;34mwandb[0m: [1mwandb sync /tmp/wandb/offline-run-20250807_122132-fmbwgrzr[0m
[1;34mwandb[0m: Find logs at: [1;35m../../../../../tmp/wandb/offline-run-20250807_122132-fmbwgrzr/logs[0m
