wandb: Using wandb-core as the SDK backend.  Please refer to https://wandb.me/wandb-core for more information.
wandb: WARNING Path run/kfp-Qwen2.5-7B-Instruct/wandb/ wasn't writable, using system temp directory.
wandb: Tracking run with wandb version 0.18.7
wandb: W&B syncing is set to `offline` in this directory.  
wandb: Run `wandb online` or set WANDB_MODE=online to enable cloud syncing.
Traceback (most recent call last):
  File "/home/ilyes/ENV/lib/python3.12/site-packages/transformers/utils/hub.py", line 403, in cached_file
    resolved_file = hf_hub_download(
                    ^^^^^^^^^^^^^^^^
  File "/home/ilyes/ENV/lib/python3.12/site-packages/huggingface_hub/utils/_validators.py", line 114, in _inner_fn
    return fn(*args, **kwargs)
           ^^^^^^^^^^^^^^^^^^^
  File "/home/ilyes/ENV/lib/python3.12/site-packages/huggingface_hub/file_download.py", line 860, in hf_hub_download
    return _hf_hub_download_to_cache_dir(
           ^^^^^^^^^^^^^^^^^^^^^^^^^^^^^^
  File "/home/ilyes/ENV/lib/python3.12/site-packages/huggingface_hub/file_download.py", line 967, in _hf_hub_download_to_cache_dir
    _raise_on_head_call_error(head_call_error, force_download, local_files_only)
  File "/home/ilyes/ENV/lib/python3.12/site-packages/huggingface_hub/file_download.py", line 1476, in _raise_on_head_call_error
    raise LocalEntryNotFoundError(
huggingface_hub.errors.LocalEntryNotFoundError: Cannot find the requested files in the disk cache and outgoing traffic has been disabled. To enable hf.co look-ups and downloads online, set 'local_files_only' to False.

The above exception was the direct cause of the following exception:

Traceback (most recent call last):
  File "/scratch/ilyes/kfp-gen/finetuning/unsloth_trainer/train_sft.py", line 130, in <module>
    main()
  File "/scratch/ilyes/kfp-gen/finetuning/unsloth_trainer/train_sft.py", line 45, in main
    model = AutoModelForCausalLM.from_pretrained(
            ^^^^^^^^^^^^^^^^^^^^^^^^^^^^^^^^^^^^^
  File "/home/ilyes/ENV/lib/python3.12/site-packages/transformers/models/auto/auto_factory.py", line 526, in from_pretrained
    config, kwargs = AutoConfig.from_pretrained(
                     ^^^^^^^^^^^^^^^^^^^^^^^^^^^
  File "/home/ilyes/ENV/lib/python3.12/site-packages/transformers/models/auto/configuration_auto.py", line 1054, in from_pretrained
    config_dict, unused_kwargs = PretrainedConfig.get_config_dict(pretrained_model_name_or_path, **kwargs)
                                 ^^^^^^^^^^^^^^^^^^^^^^^^^^^^^^^^^^^^^^^^^^^^^^^^^^^^^^^^^^^^^^^^^^^^^^^^^
  File "/home/ilyes/ENV/lib/python3.12/site-packages/transformers/configuration_utils.py", line 591, in get_config_dict
    config_dict, kwargs = cls._get_config_dict(pretrained_model_name_or_path, **kwargs)
                          ^^^^^^^^^^^^^^^^^^^^^^^^^^^^^^^^^^^^^^^^^^^^^^^^^^^^^^^^^^^^^
  File "/home/ilyes/ENV/lib/python3.12/site-packages/transformers/configuration_utils.py", line 650, in _get_config_dict
    resolved_config_file = cached_file(
                           ^^^^^^^^^^^^
  File "/home/ilyes/ENV/lib/python3.12/site-packages/transformers/utils/hub.py", line 446, in cached_file
    raise EnvironmentError(
OSError: We couldn't connect to 'https://huggingface.co' to load this file, couldn't find it in the cached files and it looks like Qwen/Qwen2.5-7B-Instruct is not the path to a directory containing a file named config.json.
Checkout your internet connection or see how to run the library in offline mode at 'https://huggingface.co/docs/transformers/installation#offline-mode'.
[1;34mwandb[0m:
[1;34mwandb[0m: You can sync this run to the cloud by running:
[1;34mwandb[0m: [1mwandb sync /tmp/wandb/offline-run-20250807_122759-js6zncb8[0m
[1;34mwandb[0m: Find logs at: [1;35m../../../../../tmp/wandb/offline-run-20250807_122759-js6zncb8/logs[0m
