Traceback (most recent call last):
  File "/home/ilyes/ENV/lib/python3.12/site-packages/transformers/utils/import_utils.py", line 1817, in _get_module
    return importlib.import_module("." + module_name, self.__name__)
           ^^^^^^^^^^^^^^^^^^^^^^^^^^^^^^^^^^^^^^^^^^^^^^^^^^^^^^^^^
  File "/cvmfs/soft.computecanada.ca/easybuild/software/2023/x86-64-v3/Compiler/gcccore/python/3.12.4/lib/python3.12/importlib/__init__.py", line 90, in import_module
    return _bootstrap._gcd_import(name[level:], package, level)
           ^^^^^^^^^^^^^^^^^^^^^^^^^^^^^^^^^^^^^^^^^^^^^^^^^^^^
  File "<frozen importlib._bootstrap>", line 1387, in _gcd_import
  File "<frozen importlib._bootstrap>", line 1360, in _find_and_load
  File "<frozen importlib._bootstrap>", line 1331, in _find_and_load_unlocked
  File "<frozen importlib._bootstrap>", line 935, in _load_unlocked
  File "<frozen importlib._bootstrap_external>", line 995, in exec_module
  File "<frozen importlib._bootstrap>", line 488, in _call_with_frames_removed
  File "/home/ilyes/ENV/lib/python3.12/site-packages/transformers/generation/utils.py", line 53, in <module>
    from .candidate_generator import (
  File "/home/ilyes/ENV/lib/python3.12/site-packages/transformers/generation/candidate_generator.py", line 26, in <module>
    from sklearn.metrics import roc_curve
  File "/home/ilyes/ENV/lib/python3.12/site-packages/sklearn/__init__.py", line 73, in <module>
    from .base import clone  # noqa: E402
    ^^^^^^^^^^^^^^^^^^^^^^^
  File "/home/ilyes/ENV/lib/python3.12/site-packages/sklearn/base.py", line 19, in <module>
    from .utils._estimator_html_repr import _HTMLDocumentationLinkMixin, estimator_html_repr
  File "/home/ilyes/ENV/lib/python3.12/site-packages/sklearn/utils/__init__.py", line 15, in <module>
    from ._chunking import gen_batches, gen_even_slices
  File "/home/ilyes/ENV/lib/python3.12/site-packages/sklearn/utils/_chunking.py", line 11, in <module>
    from ._param_validation import Interval, validate_params
  File "/home/ilyes/ENV/lib/python3.12/site-packages/sklearn/utils/_param_validation.py", line 14, in <module>
    from scipy.sparse import csr_matrix, issparse
ModuleNotFoundError: No module named 'scipy'

The above exception was the direct cause of the following exception:

Traceback (most recent call last):
  File "/home/ilyes/ENV/lib/python3.12/site-packages/transformers/utils/import_utils.py", line 1817, in _get_module
    return importlib.import_module("." + module_name, self.__name__)
           ^^^^^^^^^^^^^^^^^^^^^^^^^^^^^^^^^^^^^^^^^^^^^^^^^^^^^^^^^
  File "/cvmfs/soft.computecanada.ca/easybuild/software/2023/x86-64-v3/Compiler/gcccore/python/3.12.4/lib/python3.12/importlib/__init__.py", line 90, in import_module
    return _bootstrap._gcd_import(name[level:], package, level)
           ^^^^^^^^^^^^^^^^^^^^^^^^^^^^^^^^^^^^^^^^^^^^^^^^^^^^
  File "<frozen importlib._bootstrap>", line 1387, in _gcd_import
  File "<frozen importlib._bootstrap>", line 1360, in _find_and_load
  File "<frozen importlib._bootstrap>", line 1331, in _find_and_load_unlocked
  File "<frozen importlib._bootstrap>", line 935, in _load_unlocked
  File "<frozen importlib._bootstrap_external>", line 995, in exec_module
  File "<frozen importlib._bootstrap>", line 488, in _call_with_frames_removed
  File "/home/ilyes/ENV/lib/python3.12/site-packages/transformers/models/auto/modeling_auto.py", line 21, in <module>
    from .auto_factory import (
  File "/home/ilyes/ENV/lib/python3.12/site-packages/transformers/models/auto/auto_factory.py", line 40, in <module>
    from ...generation import GenerationMixin
  File "<frozen importlib._bootstrap>", line 1412, in _handle_fromlist
  File "/home/ilyes/ENV/lib/python3.12/site-packages/transformers/utils/import_utils.py", line 1805, in __getattr__
    module = self._get_module(self._class_to_module[name])
             ^^^^^^^^^^^^^^^^^^^^^^^^^^^^^^^^^^^^^^^^^^^^^
  File "/home/ilyes/ENV/lib/python3.12/site-packages/transformers/utils/import_utils.py", line 1819, in _get_module
    raise RuntimeError(
RuntimeError: Failed to import transformers.generation.utils because of the following error (look up to see its traceback):
No module named 'scipy'

The above exception was the direct cause of the following exception:

Traceback (most recent call last):
  File "/scratch/ilyes/kfp-gen/finetuning/test_qwen/./eval.py", line 37, in <module>
    from transformers import AutoModelForCausalLM, AutoTokenizer
  File "<frozen importlib._bootstrap>", line 1412, in _handle_fromlist
  File "/home/ilyes/ENV/lib/python3.12/site-packages/transformers/utils/import_utils.py", line 1806, in __getattr__
    value = getattr(module, name)
            ^^^^^^^^^^^^^^^^^^^^^
  File "/home/ilyes/ENV/lib/python3.12/site-packages/transformers/utils/import_utils.py", line 1805, in __getattr__
    module = self._get_module(self._class_to_module[name])
             ^^^^^^^^^^^^^^^^^^^^^^^^^^^^^^^^^^^^^^^^^^^^^
  File "/home/ilyes/ENV/lib/python3.12/site-packages/transformers/utils/import_utils.py", line 1819, in _get_module
    raise RuntimeError(
RuntimeError: Failed to import transformers.models.auto.modeling_auto because of the following error (look up to see its traceback):
Failed to import transformers.generation.utils because of the following error (look up to see its traceback):
No module named 'scipy'
